------------------------------------------------------------------------------
- SDAPS -- setup
------------------------------------------------------------------------------
Running pdflatex now multiple times to generate the questionnaire.
Running pdflatex now multiple imes to generate the questionnaire.
Financial Literacy
Author: None
------------------------------------------------------------------------------
- SDAPS -- annotate
------------------------------------------------------------------------------
/usr/lib/python3/dist-packages/sdaps/annotate/__init__.py:18: PyGIWarning: Poppler was imported without specifying a version first. Use gi.require_version('Poppler', '0.18') before import to ensure that the right version gets loaded.
  from gi.repository import Poppler
/usr/lib/python3/dist-packages/sdaps/annotate/buddies.py:21: PyGIWarning: Pango was imported without specifying a version first. Use gi.require_version('Pango', '1.0') before import to ensure that the right version gets loaded.
  from gi.repository import Pango
/usr/lib/python3/dist-packages/sdaps/annotate/buddies.py:22: PyGIWarning: PangoCairo was imported without specifying a version first. Use gi.require_version('PangoCairo', '1.0') before import to ensure that the right version gets loaded.
  from gi.repository import PangoCairo
------------------------------------------------------------------------------
- SDAPS -- annotate
------------------------------------------------------------------------------
/usr/lib/python3/dist-packages/sdaps/annotate/__init__.py:18: PyGIWarning: Poppler was imported without specifying a version first. Use gi.require_version('Poppler', '0.18') before import to ensure that the right version gets loaded.
  from gi.repository import Poppler
/usr/lib/python3/dist-packages/sdaps/annotate/buddies.py:21: PyGIWarning: Pango was imported without specifying a version first. Use gi.require_version('Pango', '1.0') before import to ensure that the right version gets loaded.
  from gi.repository import Pango
/usr/lib/python3/dist-packages/sdaps/annotate/buddies.py:22: PyGIWarning: PangoCairo was imported without specifying a version first. Use gi.require_version('PangoCairo', '1.0') before import to ensure that the right version gets loaded.
  from gi.repository import PangoCairo
------------------------------------------------------------------------------
- SDAPS -- add
------------------------------------------------------------------------------
Converting input files into a single temporary file.
Processing /tmp/sdaps-convert-2l0gt_t1.tif
Done
------------------------------------------------------------------------------
- SDAPS -- gui
------------------------------------------------------------------------------
Traceback (most recent call last):
  File "/usr/lib/python3/dist-packages/sdaps/gui/__init__.py", line 370, in page_number_combo_changed_cb
    self.provider.image.page_number = None
  File "/usr/lib/python3/dist-packages/sdaps/model/sheet.py", line 201, in __setattr__
    self.sheet.survey.questionnaire.notify_data_changed(None, None, attr, old_value)
  File "/usr/lib/python3/dist-packages/sdaps/model/questionnaire.py", line 85, in notify_data_changed
    func(self, qobj, dobj, name, old_value)
  File "/usr/lib/python3/dist-packages/sdaps/gui/widget_buddies.py", line 49, in data_changed
    self.sync_state()
  File "/usr/lib/python3/dist-packages/sdaps/gui/widget_buddies.py", line 118, in sync_state
    self.page_verified_checkbox.set_active(self._current_image.verified)
AttributeError: 'NoneType' object has no attribute 'verified'
------------------------------------------------------------------------------
- SDAPS -- gui
------------------------------------------------------------------------------
Traceback (most recent call last):
  File "/usr/lib/python3/dist-packages/sdaps/gui/__init__.py", line 370, in page_number_combo_changed_cb
    self.provider.image.page_number = None
  File "/usr/lib/python3/dist-packages/sdaps/model/sheet.py", line 201, in __setattr__
    self.sheet.survey.questionnaire.notify_data_changed(None, None, attr, old_value)
  File "/usr/lib/python3/dist-packages/sdaps/model/questionnaire.py", line 85, in notify_data_changed
    func(self, qobj, dobj, name, old_value)
  File "/usr/lib/python3/dist-packages/sdaps/gui/widget_buddies.py", line 49, in data_changed
    self.sync_state()
  File "/usr/lib/python3/dist-packages/sdaps/gui/widget_buddies.py", line 118, in sync_state
    self.page_verified_checkbox.set_active(self._current_image.verified)
AttributeError: 'NoneType' object has no attribute 'verified'
------------------------------------------------------------------------------
- SDAPS -- ids
------------------------------------------------------------------------------
------------------------------------------------------------------------------
- SDAPS -- ids
------------------------------------------------------------------------------
------------------------------------------------------------------------------
- SDAPS -- recognize
------------------------------------------------------------------------------
4 sheets
Warning: Got a wrong survey ID (1.tif, 3)! It is 250950495, but should be 4003866905.
Processed 4 of 4 sheets, took 8.029831 seconds
------------------------------------------------------------------------------
- SDAPS -- ids
------------------------------------------------------------------------------
------------------------------------------------------------------------------
- SDAPS -- info
------------------------------------------------------------------------------
Existing fields:
title
Author
------------------------------------------------------------------------------
- SDAPS -- gui
------------------------------------------------------------------------------
------------------------------------------------------------------------------
- SDAPS -- report
------------------------------------------------------------------------------
------------------------------------------------------------------------------
- SDAPS -- report
------------------------------------------------------------------------------
------------------------------------------------------------------------------
- SDAPS -- report_tex
------------------------------------------------------------------------------
Running pdflatex now multiple times to generate the report.
Error running "pdflatex" to compile the LaTeX file.
An occured during creation of the report. Temporary files left in '/tmp/sdaps-report-dbzelnee'.
Traceback (most recent call last):
  File "/usr/lib/python3/dist-packages/sdaps/__init__.py", line 65, in main
    return cmdline['_func'](cmdline)
  File "/usr/lib/python3/dist-packages/sdaps/script.py", line 118, in decorated_function
    result = function(cmdline)
  File "/usr/lib/python3/dist-packages/sdaps/cmdline/reporttex.py", line 61, in report_tex
    return reporttex.report(survey, cmdline['filter'], cmdline['output'], cmdline['papersize'], suppress=cmdline['suppress'], tex_only=cmdline['create-tex'])
  File "/usr/lib/python3/dist-packages/sdaps/reporttex/__init__.py", line 163, in report
    raise AssertionError('PDF file not generated')
AssertionError: PDF file not generated
------------------------------------------------------------------------------
- SDAPS -- gui
------------------------------------------------------------------------------
------------------------------------------------------------------------------
- SDAPS -- report
------------------------------------------------------------------------------
------------------------------------------------------------------------------
- SDAPS -- report_tex
------------------------------------------------------------------------------
Running pdflatex now multiple times to generate the report.
Error running "pdflatex" to compile the LaTeX file.
An occured during creation of the report. Temporary files left in '/tmp/sdaps-report-l7ftub_c'.
Traceback (most recent call last):
  File "/usr/lib/python3/dist-packages/sdaps/__init__.py", line 65, in main
    return cmdline['_func'](cmdline)
  File "/usr/lib/python3/dist-packages/sdaps/script.py", line 118, in decorated_function
    result = function(cmdline)
  File "/usr/lib/python3/dist-packages/sdaps/cmdline/reporttex.py", line 61, in report_tex
    return reporttex.report(survey, cmdline['filter'], cmdline['output'], cmdline['papersize'], suppress=cmdline['suppress'], tex_only=cmdline['create-tex'])
  File "/usr/lib/python3/dist-packages/sdaps/reporttex/__init__.py", line 163, in report
    raise AssertionError('PDF file not generated')
AssertionError: PDF file not generated
------------------------------------------------------------------------------
- SDAPS -- report_tex
------------------------------------------------------------------------------
Running pdflatex now multiple times to generate the report.
Error running "pdflatex" to compile the LaTeX file.
An occured during creation of the report. Temporary files left in '/tmp/sdaps-report-9ckliywz'.
Traceback (most recent call last):
  File "/usr/lib/python3/dist-packages/sdaps/__init__.py", line 65, in main
    return cmdline['_func'](cmdline)
  File "/usr/lib/python3/dist-packages/sdaps/script.py", line 118, in decorated_function
    result = function(cmdline)
  File "/usr/lib/python3/dist-packages/sdaps/cmdline/reporttex.py", line 61, in report_tex
    return reporttex.report(survey, cmdline['filter'], cmdline['output'], cmdline['papersize'], suppress=cmdline['suppress'], tex_only=cmdline['create-tex'])
  File "/usr/lib/python3/dist-packages/sdaps/reporttex/__init__.py", line 163, in report
    raise AssertionError('PDF file not generated')
AssertionError: PDF file not generated
------------------------------------------------------------------------------
- SDAPS -- csvdata
------------------------------------------------------------------------------
------------------------------------------------------------------------------
- SDAPS -- gui
------------------------------------------------------------------------------
------------------------------------------------------------------------------
- SDAPS -- report_tex
------------------------------------------------------------------------------
Running pdflatex now multiple times to generate the report.
Error running "pdflatex" to compile the LaTeX file.
An occured during creation of the report. Temporary files left in '/tmp/sdaps-report-o7u8q6cl'.
Traceback (most recent call last):
  File "/usr/lib/python3/dist-packages/sdaps/__init__.py", line 65, in main
    return cmdline['_func'](cmdline)
  File "/usr/lib/python3/dist-packages/sdaps/script.py", line 118, in decorated_function
    result = function(cmdline)
  File "/usr/lib/python3/dist-packages/sdaps/cmdline/reporttex.py", line 61, in report_tex
    return reporttex.report(survey, cmdline['filter'], cmdline['output'], cmdline['papersize'], suppress=cmdline['suppress'], tex_only=cmdline['create-tex'])
  File "/usr/lib/python3/dist-packages/sdaps/reporttex/__init__.py", line 163, in report
    raise AssertionError('PDF file not generated')
AssertionError: PDF file not generated
